<?xml version="1.0" ?>
<!-- =================================================================================== -->
<!-- |    This document was autogenerated by xacro from kr210.urdf.xacro               | -->
<!-- |    EDITING THIS FILE BY HAND IS NOT RECOMMENDED                                 | -->
<!-- =================================================================================== -->
<robot name="kuka_kr210_arm">
  <!-- Link0 -->
  <gazebo reference="base_link">
    <material>Gazebo/Red</material>
    <mu1>2</mu1>
    <mu2>2</mu2>
  </gazebo>
  <!-- Link1 -->
  <gazebo reference="link_1">
    <mu1>0.2</mu1>
    <mu2>0.2</mu2>
  </gazebo>
  <!-- Link2 -->
  <gazebo reference="link_2">
    <mu1>0.2</mu1>
    <mu2>0.2</mu2>
  </gazebo>
  <!-- Link3 -->
  <gazebo reference="link_3">
    <mu1>0.2</mu1>
    <mu2>0.2</mu2>
  </gazebo>
  <!-- Link4 -->
  <gazebo reference="link_4">
    <mu1>0.2</mu1>
    <mu2>0.2</mu2>
  </gazebo>
  <!-- Link5 -->
  <gazebo reference="link_5">
    <mu1>0.2</mu1>
    <mu2>0.2</mu2>
  </gazebo>
  <!-- Link6 -->
  <gazebo reference="link_6">
    <mu1>0.2</mu1>
    <mu2>0.2</mu2>
  </gazebo>
  <!-- Gripper -->
  <gazebo reference="gripper_link">
    <material>Gazebo/Red</material>
    <mu1>0.2</mu1>
    <mu2>0.2</mu2>
  </gazebo>
  <gazebo reference="left_gripper_finger_link">
    <material>Gazebo/Red</material>
    <kp>1000000.0</kp>
    <kd>1.0</kd>
    <mu1>30.0</mu1>
    <mu2>30.0</mu2>
  </gazebo>
  <gazebo reference="right_gripper_finger_link">
    <material>Gazebo/Red</material>
    <kp>1000000.0</kp>
    <kd>1.0</kd>
    <mu1>30.0</mu1>
    <mu2>30.0</mu2>
  </gazebo>
-->

  <!-- grasp plugin -->
  <gazebo>
    <plugin filename="libgazebo_grasp_fix.so" name="gazebo_grasp_fix">
      <arm>
        <arm_name>kuka_arm</arm_name>
        <palm_link>link_6</palm_link>
        <gripper_link>right_gripper_finger_link</gripper_link>
        <gripper_link>left_gripper_finger_link</gripper_link>
      </arm>
      <forces_angle_tolerance>100</forces_angle_tolerance>
      <update_rate>4</update_rate>
      <grip_count_threshold>4</grip_count_threshold>
      <max_grip_count>8</max_grip_count>
      <release_tolerance>0.003</release_tolerance>
      <disable_collisions_on_attach>false</disable_collisions_on_attach>
      <contact_topic>_default_topic_</contact_topic>
    </plugin>
  </gazebo>
  <!--Links-->
  <link name="base_footprint"/>
  <link name="base_link">
    <inertial>
      <origin rpy="0 0 0" xyz="0 0 0"/>
      <mass value="150"/>
      <inertia ixx="60" ixy="0" ixz="0" iyy="70" iyz="0" izz="100"/>
    </inertial>
    <visual>
      <origin rpy="0 0 0" xyz="0 0 0"/>
      <geometry>
        <mesh filename="package://kuka_kr210_arm/meshes/visual/chasis.dae"/>
      </geometry>
      <material name="">
        <color rgba="0.75294 0.75294 0.75294 1"/>
      </material>
    </visual>
    <collision>
      <origin rpy="0 0 0" xyz="0 0 0"/>
      <geometry>
        <mesh filename="package://kuka_kr210_arm/meshes/collision/chasis.stl"/>
      </geometry>
    </collision>
  </link>
  <link name="link_1">
    <inertial>
      <origin rpy="1.5 0 0" xyz="0 0 0.4"/>
      <mass value="138"/>
      <inertia ixx="30" ixy="0" ixz="0" iyy="50" iyz="0" izz="50"/>
    </inertial>
    <visual>
      <origin rpy="0 0 0" xyz="0 0 0"/>
      <geometry>
        <mesh filename="package://kuka_kr210_arm/meshes/visual/wheel1.dae"/>
      </geometry>
      <material name="green">
        <color rgba="0.75294 0.75294 0.75294 1"/>
      </material>
    </visual>
    <collision>
      <origin rpy="0 90 0" xyz="-4.4917 2.9837 -0.00299"/>
      <geometry>
        <mesh filename="package://kuka_kr210_arm/meshes/collision/wheel1.stl"/>
      </geometry>
    </collision>
  </link>
  <link name="link_2">
    <inertial>
      <origin rpy="0 0 0" xyz="0 0 0"/>
      <mass value="95"/>
      <inertia ixx="40" ixy="0" ixz="0" iyy="40" iyz="0" izz="10"/>
    </inertial>
    <visual>
      <origin rpy="0 0 0" xyz="0 0 0"/>
      <geometry>
        <mesh filename="package://kuka_kr210_arm/meshes/visual/wheel2.dae"/>
      </geometry>
      <material name="">
        <color rgba="0.75294 0.75294 0.75294 1"/>
      </material>
    </visual>
    <collision>
      <origin rpy="0 0 0" xyz="0 0 0"/>
      <geometry>
        <mesh filename="package://kuka_kr210_arm/meshes/collision/wheel2.stl"/>
      </geometry>
    </collision>
  </link>
  <link name="link_3">
    <inertial>
      <origin rpy="0 0 0" xyz="0.18842 0.18344 -0.042799"/>
      <mass value="71"/>
      <inertia ixx="1" ixy="0" ixz="0" iyy="10" iyz="0" izz="10"/>
    </inertial>
    <visual>
      <origin rpy="0 0 0" xyz="0 0 0"/>
      <geometry>
        <mesh filename="package://kuka_kr210_arm/meshes/visual/wheel3.dae"/>
      </geometry>
      <material name="">
        <color rgba="0.75294 0.75294 0.75294 1"/>
      </material>
    </visual>
    <collision>
      <origin rpy="0 0 0" xyz="0 0 0"/>
      <geometry>
        <mesh filename="package://kuka_kr210_arm/meshes/collision/wheel3.stl"/>
      </geometry>
    </collision>
  </link>
  <link name="link_4">
    <inertial>
      <origin rpy="0 0 0" xyz="0 0 0"/>
      <mass value="17"/>
      <inertia ixx="0.18" ixy="0" ixz="0" iyy="0.55" iyz="0" izz="0.64"/>
    </inertial>
    <visual>
      <origin rpy="0 0 0" xyz="0 0 0"/>
      <geometry>
        <mesh filename="package://kuka_kr210_arm/meshes/visual/wheel4.dae"/>
      </geometry>
      <material name="">
        <color rgba="0.75294 0.75294 0.75294 1"/>
      </material>
    </visual>
    <collision>
      <origin rpy="0 0 0" xyz="0 0 0"/>
      <geometry>
        <mesh filename="package://kuka_kr210_arm/meshes/collision/wheel4.stl"/>
      </geometry>
    </collision>
  </link>
  <link name="link_5">
    <inertial>
      <origin rpy="0 0 0" xyz="0 0 0"/>
      <mass value="7"/>
      <inertia ixx="0.04" ixy="0" ixz="0" iyy="0.068" iyz="0" izz="0.068"/>
    </inertial>
    <visual>
      <origin rpy="-1.570796327 0 0" xyz="0 0 0"/>
      <geometry>
        <mesh filename="package://kuka_kr210_arm/meshes/visual/insidebelt.dae"/>
      </geometry>
      <material name="">
        <color rgba="0.75294 0.75294 0.75294 1"/>
      </material>
    </visual>
    <collision>
      <origin rpy="0 0 0" xyz="0 0 0"/>
      <geometry>
        <mesh filename="package://kuka_kr210_arm/meshes/collision/insidebelt.stl"/>
      </geometry>
    </collision>
  </link>
  <link name="link_6">
    <inertial>
      <origin rpy="0 0 0" xyz="0 0 0"/>
      <mass value="0.5"/>
      <inertia ixx="0.004" ixy="0" ixz="0" iyy="0.003" iyz="0" izz="0.003"/>
    </inertial>
    <visual>
      <origin rpy="0 0 0" xyz="0 0 0"/>
      <geometry>
        <mesh filename="package://kuka_kr210_arm/meshes/visual/oo.dae"/>
      </geometry>
      <material name="">
        <color rgba="0.75294 0.75294 0.75294 1"/>
      </material>
    </visual>
    <collision>
      <origin rpy="0 0 0" xyz="0 0 0"/>
      <geometry>
        <mesh filename="package://kuka_kr210_arm/meshes/collision/oo.stl"/>
      </geometry>
    </collision>
  </link>
  <link name="messLink">
    <inertial>
      <origin rpy="0 0 0" xyz="0 0 0"/>
      <mass value="0.5"/>
      <inertia ixx="0.004" ixy="0" ixz="0" iyy="0.003" iyz="0" izz="0.003"/>
    </inertial>
    <visual>
      <origin rpy="0 0 0" xyz="0 0 0"/>
      <geometry>
        <mesh filename="package://kuka_kr210_arm/meshes/visual/m2.dae"/>
      </geometry>
      <material name="">
        <color rgba="0.75294 0.75294 0.75294 1"/>
      </material>
    </visual>
    <collision>
      <origin rpy="0 0 0" xyz="0 0 0"/>
      <geometry>
        <mesh filename="package://kuka_kr210_arm/meshes/collision/m2.stl"/>
      </geometry>
    </collision>
  </link>
  <link name="height">
    <inertial>
      <origin rpy="0 0 0" xyz="0 0 0"/>
      <mass value="0.3"/>
      <inertia ixx="0.0001" ixy="0" ixz="0" iyy="0.0002" iyz="0" izz="0.0001"/>
    </inertial>
    <visual>
      <origin rpy="0 0 0" xyz="0 0 0"/>
      <geometry>
        <mesh filename="package://kuka_kr210_arm/meshes/visual/height.dae"/>
      </geometry>
    </visual>
    <collision>
      <origin rpy="0 0 0" xyz="0 0 0"/>
      <geometry>
        <mesh filename="package://kuka_kr210_arm/meshes/visual/height.stl"/>
      </geometry>
    </collision>
  </link>
  
  <link name="gripper_link">
    <inertial>
      <origin rpy="0 0 0" xyz="0 0 0"/>
      <mass value="0.3"/>
      <inertia ixx="0.0001" ixy="0" ixz="0" iyy="0.0002" iyz="0" izz="0.0001"/>
    </inertial>
    <visual>
      <origin rpy="0 0 0" xyz="0 0 0"/>
      <geometry>
        <mesh filename="package://kuka_kr210_arm/meshes/visual/fan.dae"/>
      </geometry>
    </visual>
    <collision>
      <origin rpy="0 0 0" xyz="0 0 0"/>
      <geometry>
        <mesh filename="package://kuka_kr210_arm/meshes/visual/fan.stl"/>
      </geometry>
    </collision>
  </link>
   <link name="camera">
    <inertial>
      <origin rpy="0 0 0" xyz="0 0 0"/>
      <mass value="0.3"/>
      <inertia ixx="0.0001" ixy="0" ixz="0" iyy="0.0002" iyz="0" izz="0.0001"/>
    </inertial>
    <visual>
      <origin rpy="0 0 0" xyz="0 0 0"/>
      <geometry>
        <mesh filename="package://kuka_kr210_arm/meshes/visual/mcam.dae"/>
      </geometry>
    </visual>
    <collision>
      <origin rpy="0 0 0" xyz="0 0 0"/>
      <geometry>
        <mesh filename="package://kuka_kr210_arm/meshes/visual/mcam.stl"/>
      </geometry>
    </collision>
  </link>
  <link name="right_gripper_finger_link">
    <inertial>
      <origin rpy="0 0 0" xyz="0 0 0"/>
      <mass value="0.1"/>
      <inertia ixx="0.002" ixy="0" ixz="0" iyy="0.0002" iyz="0" izz="0.0002"/>
    </inertial>
    <visual>
      <origin rpy="0 0 0" xyz="0 0 0"/>
      <geometry>
        <mesh filename="package://kuka_kr210_arm/meshes/visual/mcam2.dae"/>
      </geometry>
    </visual>
    <collision>
      <origin rpy="0 0 0" xyz="0 0 0"/>
      <geometry>
        <mesh filename="package://kuka_kr210_arm/meshes/collision/mcam2.stl"/>
      </geometry>
    </collision>
  </link>
  <link name="left_gripper_finger_link">
    <inertial>
      <origin rpy="0 0 0" xyz="0 0 0"/>
      <mass value="0.1"/>
      <inertia ixx="0.002" ixy="0" ixz="0" iyy="0.0002" iyz="0" izz="0.0002"/>
    </inertial>
    <visual>
      <origin rpy="0 0 0" xyz="0 0 0"/>
      <geometry>
        <mesh filename="package://kuka_kr210_arm/meshes/visual/towers.dae"/>
      </geometry>
    </visual>
    <collision>
      <origin rpy="0 0 0" xyz="0 0 0"/>
      <geometry>
        <mesh filename="package://kuka_kr210_arm/meshes/collision/towers.stl"/>
      </geometry>
    </collision>
  </link>
   <link name="pipe">
    <inertial>
      <origin rpy="0 0 0" xyz="0 0 0"/>
      <mass value="0.1"/>
      <inertia ixx="0.002" ixy="0" ixz="0" iyy="0.0002" iyz="0" izz="0.0002"/>
    </inertial>
    <visual>
      <origin rpy="0 0 0" xyz="0 0 0"/>
      <geometry>
        <mesh filename="package://kuka_kr210_arm/meshes/visual/pipe.dae"/>
      </geometry>
    </visual>
    <collision>
      <origin rpy="0 0 0" xyz="0 0 0"/>
      <geometry>
        <mesh filename="package://kuka_kr210_arm/meshes/collision/pipe.stl"/>
      </geometry>
    </collision>
  </link>

  <joint name="mess_to_chasis" type="fixed">
    <origin rpy="0 0 0" xyz="-4 -6.5 -1.2"/>
    <parent link="base_link"/>
    <child link="messLink"/>
    <axis xyz="0 1 0"/>
    <limit effort="100" lower="-0.01" upper="0.06" velocity="0.05"/>
    <dynamics damping="0.7"/>
  </joint>
  <joint name="mess_to_height" type="fixed">
    <origin rpy="0 0 0" xyz="-4 -3 0.0"/>
    <parent link="base_link"/>
    <child link="height"/>
    <axis xyz="0 1 0"/>
    <limit effort="100" lower="-0.01" upper="0.06" velocity="0.05"/>
    <dynamics damping="0.7"/>
  </joint>
  <joint name="cam_to_baselink" type="fixed">
    <origin rpy="0 0 0" xyz="-1.7 4.9 1.2"/>
    <parent link="base_link"/>
    <child link="camera"/>
    <axis xyz="0 1 0"/>
    <limit effort="100" lower="-0.01" upper="0.06" velocity="0.05"/>
    <dynamics damping="0.7"/>
  </joint>
  <joint name="right_gripper_finger_joint" type="fixed">
    <origin rpy="0 0 0" xyz="-6 4.9 1.2"/>
    <parent link="base_link"/>
    <child link="right_gripper_finger_link"/>
    <axis xyz="0 1 0"/>
    <limit effort="100" lower="-0.01" upper="0.06" velocity="0.05"/>
    <dynamics damping="0.7"/>
  </joint>
  <joint name="left_gripper_finger_joint" type="prismatic">
    <origin rpy="0 0 0" xyz="-4 -3 0"/>
    <parent link="base_link"/>
    <child link="left_gripper_finger_link"/>
    <axis xyz="0 -1 0"/>
    <limit effort="100" lower="-0.01" upper="0.06" velocity="0.05"/>
    <dynamics damping="0.7"/>
  </joint>
  <joint name="fan" type="fixed">
    <parent link="pipe"/>
    <child link="gripper_link"/>
    <origin rpy="0 0 0" xyz="-0.1 0 0"/>
    <!--0.087-->
    <axis xyz="1 0 0"/>
  </joint>
  <!-- joints -->
  <joint name="fixed_base_joint" type="fixed">
    <parent link="base_footprint"/>
    <child link="base_link"/>
    <origin rpy="0 0 0" xyz="0 0 0"/>
  </joint>
  <joint name="joint_1" type="continuous">
  <limit effort="1000" lower="-0" upper="0" velocity="0.5"/>
  <axis xyz="0 1 0"/>
    <origin rpy="0 0 1.57" xyz="0.5 0 0"/>
    <parent link="base_link"/>
    <child link="link_1"/>
    <axis xyz="0 0 -1"/>
     <limit effort="100" lower="-5" upper="5" velocity="0.8"/>
  </joint>
  <joint name="joint_2" type="revolute">
    <origin rpy="0 0 1.57" xyz="-8.5 0 0"/>
    <parent link="base_link"/>
    <child link="link_2"/>
    <axis xyz="0 1 0"/>
	<limit effort="100" lower="-5" upper="5" velocity="0.8"/>
  </joint>
  <joint name="joint_3" type="revolute">
    <origin rpy="0 0 1.57" xyz="0.5 -10 0"/>
    <parent link="base_link"/>
    <child link="link_3"/>
    <axis xyz="0 1 0"/>
	<limit effort="100" lower="-5" upper="5" velocity="0.8"/>
  </joint>
  <joint name="joint_4" type="revolute">
    <origin rpy="0 0 1.57" xyz="-8.5 -10 0"/>
    <parent link="base_link"/>
    <child link="link_4"/>
    <axis xyz="0 1 0"/>
	<limit effort="100" lower="-5" upper="5" velocity="0.8"/>
  </joint>
  <joint name="joint_5" type="fixed">
    <origin rpy="4.7 0.45 1.57" xyz="-3.9 0.6 0.72"/>
    <parent link="base_link"/>
    <child link="link_5"/>
    <axis xyz="0 1 0"/>
    <limit effort="300" lower="-2.1816616250000003" upper="2.1816616250000003" velocity="3.0019663960000003"/>
  </joint>
  <joint name="joint_6" type="revolute">
    <origin rpy="6.27 0.45 1.57" xyz="-3.9 0 0.4"/>
    <parent link="base_link"/>
    <child link="link_6"/>
    <axis xyz="1 0 0"/>
    <limit effort="300" lower="-6.10865255" upper="6.10865255" velocity="3.8222711670000002"/>
  </joint>
 <joint name="base_link_pipe" type="fixed">
    <origin rpy="0 0 0" xyz="-4 -3 0.1"/>
    <parent link="base_link"/>
    <child link="pipe"/>
    <axis xyz="1 0 0"/>
    <limit effort="300" lower="-6.10865255" upper="6.10865255" velocity="3.8222711670000002"/>
  </joint>



  <gazebo>
    <plugin filename="libgazebo_ros2_control.so" name="gazebo_ros2_control">
      <robot_sim_type>gazebo_ros2_control/GazeboSystem</robot_sim_type>
      <parameters>package://kuka_kr210_arm/config/jtc.yaml</parameters>
    </plugin>
  </gazebo>
  


  <ros2_control name="GazeboSystem" type="system">
    <hardware>
      <plugin>gazebo_ros2_control/GazeboSystem</plugin>
  </hardware>

  <joint name="joint_1">
    <command_interface name="position">
      <param name="min">-3.14</param>
      <param name="max">3.14</param>
    </command_interface>
    <command_interface name="velocity">
      <param name="min">-3.15</param>
      <param name="max">3.15</param>
    </command_interface>
    <state_interface name="position"/>
    <state_interface name="velocity"/>
    <state_interface name="effort"/>
    <param name="initial_position">0.0</param>   
  </joint>
  <joint name="joint_2">
    <command_interface name="position">
      <param name="min">-3.14</param>
      <param name="max">3.14</param>
    </command_interface>
    <command_interface name="velocity">
      <param name="min">-3.15</param>
      <param name="max">3.15</param>
    </command_interface>
    <state_interface name="position"/>
    <state_interface name="velocity"/>
    <state_interface name="effort"/>
    <param name="initial_position">-1.57</param>   
  </joint>
  <joint name="joint_3">
    <command_interface name="position">
      <param name="min">-3.14</param>
      <param name="max">3.14</param>
    </command_interface>
    <command_interface name="velocity">
      <param name="min">-3.15</param>
      <param name="max">3.15</param>
    </command_interface>
    <state_interface name="position"/>
    <state_interface name="velocity"/>
    <state_interface name="effort"/>
    <param name="initial_position">0.0</param>   
  </joint>
  <joint name="joint_4">
    <command_interface name="position">
      <param name="min">-3.14</param>
      <param name="max">3.14</param>
    </command_interface>
    <command_interface name="velocity">
      <param name="min">-3.2</param>
      <param name="max">3.2</param>
    </command_interface>
    <state_interface name="position"/>
    <state_interface name="velocity"/>
    <state_interface name="effort"/>
    <param name="initial_position">-1.57</param>   
  </joint>
  <joint name="joint_5">
    <command_interface name="position">
      <param name="min">-3.14</param>
      <param name="max">3.14</param>
    </command_interface>
    <command_interface name="velocity">
      <param name="min">-3.2</param>
      <param name="max">3.2</param>
    </command_interface>
    <state_interface name="position"/>
    <state_interface name="velocity"/>
    <state_interface name="effort"/>
    <param name="initial_position">0.0</param>   
  </joint>
  <joint name="joint_6">
    <command_interface name="position">
      <param name="min">-3.14</param>
      <param name="max">3.14</param>
    </command_interface>
    <command_interface name="velocity">
      <param name="min">-3.2</param>
      <param name="max">3.2</param>
    </command_interface>
    <state_interface name="position"/>
    <state_interface name="velocity"/>
    <state_interface name="effort"/>
    <param name="initial_position">0.0</param>   
  </joint>

  <joint name="right_gripper_finger_joint">
    <command_interface name="position">
      <param name="min">-3.14</param>
      <param name="max">3.14</param>
    </command_interface>
    <command_interface name="velocity">
      <param name="min">-3.2</param>
      <param name="max">3.2</param>
    </command_interface>
    <state_interface name="position"/>
    <state_interface name="velocity"/>
    <state_interface name="effort"/>
    <param name="initial_position">0.0</param>   
  </joint>

  <joint name="left_gripper_finger_joint">
    <command_interface name="position">
      <param name="min">-3.14</param>
      <param name="max">3.14</param>
    </command_interface>
    <command_interface name="velocity">
      <param name="min">-3.2</param>
      <param name="max">3.2</param>
    </command_interface>
    <state_interface name="position"/>
    <state_interface name="velocity"/>
    <state_interface name="effort"/>
    <param name="initial_position">0.0</param>   
  </joint> 







</ros2_control>



</robot>
